Traceback (most recent call last):
  File "/home/zhangzishuai/anaconda3/envs/97rerank/lib/python3.9/site-packages/peft/config.py", line 184, in _get_peft_type
    config_file = hf_hub_download(
  File "/home/zhangzishuai/anaconda3/envs/97rerank/lib/python3.9/site-packages/huggingface_hub/utils/_deprecation.py", line 101, in inner_f
    return f(*args, **kwargs)
  File "/home/zhangzishuai/anaconda3/envs/97rerank/lib/python3.9/site-packages/huggingface_hub/utils/_validators.py", line 106, in _inner_fn
    validate_repo_id(arg_value)
  File "/home/zhangzishuai/anaconda3/envs/97rerank/lib/python3.9/site-packages/huggingface_hub/utils/_validators.py", line 154, in validate_repo_id
    raise HFValidationError(
huggingface_hub.errors.HFValidationError: Repo id must be in the form 'repo_name' or 'namespace/repo_name': '/home/zhangzishuai/SplitFederated-LLaMA/For_Open_Source/Fed-Llama-module/output/Friends/ReadCompre/version_3/model-A/checkpoint-5'. Use `repo_type` argument if needed.

During handling of the above exception, another exception occurred:

Traceback (most recent call last):
  File "/home/zhangzishuai/SplitFederated-LLaMA/For_Open_Source/Fed-Llama-module/flclient_llama2.py", line 1415, in <module>
    main(TemplatePrompt)
  File "/home/zhangzishuai/SplitFederated-LLaMA/For_Open_Source/Fed-Llama-module/flclient_llama2.py", line 1309, in main
    model_A = PeftModel.from_pretrained(model_A, FL_args.lora_modelA_path, device_map='auto',trust_remote_code=True)
  File "/home/zhangzishuai/anaconda3/envs/97rerank/lib/python3.9/site-packages/peft/peft_model.py", line 324, in from_pretrained
    PeftConfig._get_peft_type(
  File "/home/zhangzishuai/anaconda3/envs/97rerank/lib/python3.9/site-packages/peft/config.py", line 190, in _get_peft_type
    raise ValueError(f"Can't find '{CONFIG_NAME}' at '{model_id}'")
ValueError: Can't find 'adapter_config.json' at '/home/zhangzishuai/SplitFederated-LLaMA/For_Open_Source/Fed-Llama-module/output/Friends/ReadCompre/version_3/model-A/checkpoint-5'
